Workbook

Sheet Overview
B2: Risk factor library
B3: Northgate Bank UK Limited (fictional) | HND-CRA-002 | version 0.3 draft | September 2026
B5: What this workbook is
B6: Step 2 of the Hindsight project. It turns the framework set out in docs/01-methodology.md into a working library: 20 risk factors across the five categories required by regulation 18(2)(b) of the Money Laundering Regulations 2017, each with defined levels, a score from 1 to 5, a weight, a written rationale and a source.
B8: How to read it
B9: Categories - the five headings and their weights. These sum to 100%.
B10: Factors - the 20 factors, their weight inside their category, and their effective weight across the whole model.
B11: Levels - what each score from 1 to 5 means for each factor. An analyst selects the level that matches the evidence on file.
B12: Escalators - the mandatory High and prohibited lists from sections 5.3 and 5.4 of the methodology.
B13: Example - a worked customer, scored live from the library.
B14: Checks - arithmetic and integrity tests. Every one must read OK before the workbook is used.
B16: Which cells to edit
... B38: Synthetic and illustrative only. Northgate Bank UK Limited does not exist and no real customer data appears in this workbook. This is a self-directed learning project and is not professional compliance advice.

Sheet Categories
A1: Code | B1: Category | C1: Category weight | D1: Factors | E1: Factor weights sum | F1: Check
A2: C | B2: Customer | C2: 0.3 | D2: =COUNTIF(Factors!$B$2:$B$21,$A2) -> 5 | E2: =SUMIF(Factors!$B$2:$B$21,$A2,Factors!$D$2:$D$21) -> 1 | F2: =IF(ROUND($E2,6)=1,"OK","CHECK") -> OK
A3: G | B3: Geography | C3: 0.25 | D3: =COUNTIF(Factors!$B$2:$B$21,$A3) -> 3 | E3: =SUMIF(Factors!$B$2:$B$21,$A3,Factors!$D$2:$D$21) -> 1 | F3: =IF(ROUND($E3,6)=1,"OK","CHECK") -> OK
A4: P | B4: Product and service | C4: 0.2 | D4: =COUNTIF(Factors!$B$2:$B$21,$A4) -> 4 | E4: =SUMIF(Factors!$B$2:$B$21,$A4,Factors!$D$2:$D$21) -> 1 | F4: =IF(ROUND($E4,6)=1,"OK","CHECK") -> OK
A5: D | B5: Delivery channel | C5: 0.1 | D5: =COUNTIF(Factors!$B$2:$B$21,$A5) -> 3 | E5: =SUMIF(Factors!$B$2:$B$21,$A5,Factors!$D$2:$D$21) -> 1 | F5: =IF(ROUND($E5,6)=1,"OK","CHECK") -> OK
A6: A | B6: Expected activity | C6: 0.15 | D6: =COUNTIF(Factors!$B$2:$B$21,$A6) -> 5 | E6: =SUMIF(Factors!$B$2:$B$21,$A6,Factors!$D$2:$D$21) -> 1 | F6: =IF(ROUND($E6,6)=1,"OK","CHECK") -> OK
B7: Total | C7: =SUM($C$2:$C$6) -> 1 | F7: =IF(ROUND($C7,6)=1,"OK","CHECK") -> OK
B9: Weights are judgement, not derived from loss data. Step 5 tests their sensitivity.

Sheet Factors
A1: Factor | B1: Category | C1: Factor name | D1: Weight in category | E1: Effective weight | F1: Lowest level | G1: Highest level | H1: Rationale for the weight | I1: Source
A2: C1 | B2: C | C2: Customer legal form | D2: 0.2 | E2: =INDEX(Categories!$C$2:$C$6,MATCH($B2,Categories!$A$2:$A$6,0))*$D2 -> 0.06 | F2: =SUMPRODUCT(MIN((Levels!$A$2:$A$99=$A2)*Levels!$C$2:$C$99+(Levels!$A$2:$A$99<>$A2)*99)) -> 1 | G2: =SUMPRODUCT(MAX((Levels!$A$2:$A$99=$A2)*Levels!$C$2:$C$99)) -> 5 | H2: The legal form determines how far the Bank can see through to the natural persons behind the relationship. Reg. 33(6)(a) treats a legal person used as a vehicle for holding personal assets as a higher-risk factor. | I2: MLRs 2017 reg. 33(6)(a); JMLSG Part I ch. 5
A3: C2 | B3: C | C3: Ownership and control structure | D3: 0.2 | E3: =INDEX(Categories!$C$2:$C$6,MATCH($B3,Categories!$A$2:$A$6,0))*$D3 -> 0.06 | F3: =SUMPRODUCT(MIN((Levels!$A$2:$A$99=$A3)*Levels!$C$2:$C$99+(Levels!$A$2:$A$99<>$A3)*99)) -> 1 | G3: =SUMPRODUCT(MAX((Levels!$A$2:$A$99=$A3)*Levels!$C$2:$C$99)) -> 5 | H3: Reg. 33(6)(a) names nominee shareholders, bearer shares and an unusually complex corporate structure as higher-risk customer factors. Depth alone is not what matters: a chain of five layers the Bank can evidence at every step scores 4, while a single layer it cannot evidence scores 5, because that is the point at which the Bank stops being able to say who it is dealing with. | I3: MLRs 2017 reg. 33(6)(a); reg. 28
A4: C3 | B4: C | C4: Industry or occupation | D4: 0.25 | E4: =INDEX(Categories!$C$2:$C$6,MATCH($B4,Categories!$A$2:$A$6,0))*$D4 -> 0.075 | F4: =SUMPRODUCT(MIN((Levels!$A$2:$A$99=$A4)*Levels!$C$2:$C$99+(Levels!$A$2:$A$99<>$A4)*99)) -> 1 | G4: =SUMPRODUCT(MAX((Levels!$A$2:$A$99=$A4)*Levels!$C$2:$C$99)) -> 5 | H4: Carries the largest weight inside the customer category because sector is the most informative single thing the Bank knows about a business customer at onboarding. Reg. 33(6)(a) names cash-intensive businesses, and the National Risk Assessment 2025 names barber shops, car washes and nail salons among the prominent examples, recording a year-on-year rise in suspicious activity reports from them. Level 5 holds only the three business types that trigger escalator 5.3(c); sectors that are vulnerable without being on that list sit at level 4, so that a score of 5 and an automatic escalation always mean the same thing. | I4: MLRs 2017 reg. 33(6)(a); HM Treasury and Home Office NRA 2025; escalator 5.3(c)
A5: C4 | B5: C | C5: PEP screening outcome | D5: 0.2 | E5: =INDEX(Categories!$C$2:$C$6,MATCH($B5,Categories!$A$2:$A$6,0))*$D5 -> 0.06 | F5: =SUMPRODUCT(MIN((Levels!$A$2:$A$99=$A5)*Levels!$C$2:$C$99+(Levels!$A$2:$A$99<>$A5)*99)) -> 1 | G5: =SUMPRODUCT(MAX((Levels!$A$2:$A$99=$A5)*Levels!$C$2:$C$99)) -> 5 | H5: Scored for management information and for the record. The binding control is escalator 5.3(a), which rates any PEP, family member or known close associate High whatever this score produces, in line with the FCA's guidance as updated in July 2025. There is no level 2: a screening result is either a match or it is not, so a half-step would be a fiction. | I5: MLRs 2017 reg. 35; FCA FG17/6 as updated by FG25/3 (July 2025)
A6: C5 | B6: C | C6: Adverse media screening outcome | D6: 0.15 | E6: =INDEX(Categories!$C$2:$C$6,MATCH($B6,Categories!$A$2:$A$6,0))*$D6 -> 0.045 | F6: =SUMPRODUCT(MIN((Levels!$A$2:$A$99=$A6)*Levels!$C$2:$C$99+(Levels!$A$2:$A$99<>$A6)*99)) -> 1 | G6: =SUMPRODUCT(MAX((Levels!$A$2:$A$99=$A6)*Levels!$C$2:$C$99)) -> 5 | H6: A screening result is evidence about the customer that no other factor captures. It carries the lowest weight in the category because coverage is uneven and false positives are common. A discounted match scores 2 rather than 1 so that the fact a match occurred stays visible on the file. | I6: FCA Financial Crime Guide FCG 3; JMLSG Part I ch. 5
A7: G1 | B7: G | C7: Country of residence or incorporation | D7: 0.4 | E7: =INDEX(Categories!$C$2:$C$6,MATCH($B7,Categories!$A$2:$A$6,0))*$D7 -> 0.1 | F7: =SUMPRODUCT(MIN((Levels!$A$2:$A$99=$A7)*Levels!$C$2:$C$99+(Levels!$A$2:$A$99<>$A7)*99)) -> 1 | G7: =SUMPRODUCT(MAX((Levels!$A$2:$A$99=$A7)*Levels!$C$2:$C$99)) -> 5 | H7: Reg. 33(6)(c) requires the Bank to consider countries without effective AML systems, with significant levels of corruption, or subject to sanctions. Levels 4 and 5 are pinned to the two FATF public statements so the scale updates when FATF updates, rather than when the Bank remembers to. | I7: MLRs 2017 reg. 33(1)(b) and 33(6)(c); FATF public statements
A8: G2 | B8: G | C8: Country of tax residence where different | D8: 0.2 | E8: =INDEX(Categories!$C$2:$C$6,MATCH($B8,Categories!$A$2:$A$6,0))*$D8 -> 0.05 | F8: =SUMPRODUCT(MIN((Levels!$A$2:$A$99=$A8)*Levels!$C$2:$C$99+(Levels!$A$2:$A$99<>$A8)*99)) -> 1 | G8: =SUMPRODUCT(MAX((Levels!$A$2:$A$99=$A8)*Levels!$C$2:$C$99)) -> 5 | H8: A tax residence that differs from the residential address is a fact the Bank should be able to explain. Weighted lowest in the category because it is absent for the large majority of personal customers. | I8: JMLSG Part I ch. 5
A9: G3 | B9: G | C9: Expected counterparty or payment corridor countries | D9: 0.4 | E9: =INDEX(Categories!$C$2:$C$6,MATCH($B9,Categories!$A$2:$A$6,0))*$D9 -> 0.1 | F9: =SUMPRODUCT(MIN((Levels!$A$2:$A$99=$A9)*Levels!$C$2:$C$99+(Levels!$A$2:$A$99<>$A9)*99)) -> 1 | G9: =SUMPRODUCT(MAX((Levels!$A$2:$A$99=$A9)*Levels!$C$2:$C$99)) -> 5 | H9: For a UK-only retail bank the corridor is where country risk actually arrives, not the customer's own address. Weighted equal to G1 for that reason. | I9: MLRs 2017 reg. 33(6)(c); FATF public statements
A10: P1 | B10: P | C10: Product type held | D10: 0.35 | E10: =INDEX(Categories!$C$2:$C$6,MATCH($B10,Categories!$A$2:$A$6,0))*$D10 -> 0.07 | F10: =SUMPRODUCT(MIN((Levels!$A$2:$A$99=$A10)*Levels!$C$2:$C$99+(Levels!$A$2:$A$99<>$A10)*99)) -> 1 | G10: =SUMPRODUCT(MAX((Levels!$A$2:$A$99=$A10)*Levels!$C$2:$C$99)) -> 5 | H10: The product is the container for everything the customer can do. A business current account with cash handling and international payments carries a materially different inherent risk from an instant-access savings account before anything at all is known about the customer. | I10: MLRs 2017 reg. 18(2)(b)(iii); JMLSG Part I ch. 4
A11: P2 | B11: P | C11: Cash functionality | D11: 0.25 | E11: =INDEX(Categories!$C$2:$C$6,MATCH($B11,Categories!$A$2:$A$6,0))*$D11 -> 0.05 | F11: =SUMPRODUCT(MIN((Levels!$A$2:$A$99=$A11)*Levels!$C$2:$C$99+(Levels!$A$2:$A$99<>$A11)*99)) -> 1 | G11: =SUMPRODUCT(MAX((Levels!$A$2:$A$99=$A11)*Levels!$C$2:$C$99)) -> 5 | H11: Cash breaks the audit trail. Reg. 33(6)(a) names cash-intensive business as a higher-risk factor. The monetary thresholds in the levels are Bank policy, not a statutory figure, and are set out here so that they can be challenged and changed in one place. | I11: MLRs 2017 reg. 33(6)(a). Thresholds are an assumption of this model.
A12: P3 | B12: P | C12: International payment functionality | D12: 0.25 | E12: =INDEX(Categories!$C$2:$C$6,MATCH($B12,Categories!$A$2:$A$6,0))*$D12 -> 0.05 | F12: =SUMPRODUCT(MIN((Levels!$A$2:$A$99=$A12)*Levels!$C$2:$C$99+(Levels!$A$2:$A$99<>$A12)*99)) -> 1 | G12: =SUMPRODUCT(MAX((Levels!$A$2:$A$99=$A12)*Levels!$C$2:$C$99)) -> 5 | H12: Reg. 33(6)(b) treats products favouring anonymity and non-face-to-face arrangements as higher risk. International payment capability is the route by which geographic risk reaches an otherwise domestic customer. Level 5 is defined by reference to G3 so that the two factors cannot disagree. | I12: MLRs 2017 reg. 33(6)(b) and 33(6)(c)
A13: P4 | B13: P | C13: Third-party access to the account | D13: 0.15 | E13: =INDEX(Categories!$C$2:$C$6,MATCH($B13,Categories!$A$2:$A$6,0))*$D13 -> 0.03 | F13: =SUMPRODUCT(MIN((Levels!$A$2:$A$99=$A13)*Levels!$C$2:$C$99+(Levels!$A$2:$A$99<>$A13)*99)) -> 1 | G13: =SUMPRODUCT(MAX((Levels!$A$2:$A$99=$A13)*Levels!$C$2:$C$99)) -> 5 | H13: Reg. 33(6)(b) names payments received from unknown or unassociated third parties. Account access held by a person the Bank has not identified is the mechanism behind most money mule activity on retail accounts. | I13: MLRs 2017 reg. 33(6)(b)
... A21: A5 | B21: A | C21: Plausibility of the declared profile | D21: 0.1 | E21: =INDEX(Categories!$C$2:$C$6,MATCH($B21,Categories!$A$2:$A$6,0))*$D21 -> 0.015 | F21: =SUMPRODUCT(MIN((Levels!$A$2:$A$99=$A21)*Levels!$C$2:$C$99+(Levels!$A$2:$A$99<>$A21)*99)) -> 1 | G21: =SUMPRODUCT(MAX((Levels!$A$2:$A$99=$A21)*Levels!$C$2:$C$99)) -> 5 | H21: Deliberately given the smallest weight and the widest definition. It exists so that an analyst who sees something that does not add up has somewhere to record it inside the model rather than only in free text. Level 5 is drawn from the Monzo final notice, where customers were onboarded using well-known London landmarks as their address. | I21: FCA Final Notice, Monzo Bank Ltd, July 2025
C22: Total effective weight | E22: =SUM($E$2:$E$21) -> 1

Sheet Levels
A1: Factor | B1: Factor name | C1: Score | D1: What this level means | E1: Mandatory escalator
A2: C1 | B2: =INDEX(Factors!$C$2:$C$21,MATCH($A2,Factors!$A$2:$A$21,0)) -> Customer legal form | C2: 1 | D2: UK-resident individual, sole applicant on a personal account
A3: C1 | B3: =INDEX(Factors!$C$2:$C$21,MATCH($A3,Factors!$A$2:$A$21,0)) -> Customer legal form | C3: 2 | D3: Joint personal account between parties with an evidenced relationship, or a UK-registered sole trader
A4: C1 | B4: =INDEX(Factors!$C$2:$C$21,MATCH($A4,Factors!$A$2:$A$21,0)) -> Customer legal form | C4: 3 | D4: UK-incorporated private limited company or general partnership, all owners identified as natural persons
A5: C1 | B5: =INDEX(Factors!$C$2:$C$21,MATCH($A5,Factors!$A$2:$A$21,0)) -> Customer legal form | C5: 4 | D5: UK-incorporated entity with one or more corporate shareholders in the ownership chain, or a limited liability partnership
A6: C1 | B6: =INDEX(Factors!$C$2:$C$21,MATCH($A6,Factors!$A$2:$A$21,0)) -> Customer legal form | C6: 5 | D6: Structure including a trust, a foundation, a nominee arrangement, or an entity incorporated outside the United Kingdom anywhere in the ownership chain | E6: 5.3(d), fired on the whole level; see 5.3(d) and methodology 11.9a
A7: C2 | B7: =INDEX(Factors!$C$2:$C$21,MATCH($A7,Factors!$A$2:$A$21,0)) -> Ownership and control structure | C7: 1 | D7: Natural person; no beneficial ownership analysis required
A8: C2 | B8: =INDEX(Factors!$C$2:$C$21,MATCH($A8,Factors!$A$2:$A$21,0)) -> Ownership and control structure | C8: 2 | D8: One or two natural-person beneficial owners, each verified from an independent source
A9: C2 | B9: =INDEX(Factors!$C$2:$C$21,MATCH($A9,Factors!$A$2:$A$21,0)) -> Ownership and control structure | C9: 3 | D9: Three to five natural-person beneficial owners, all verified
A10: C2 | B10: =INDEX(Factors!$C$2:$C$21,MATCH($A10,Factors!$A$2:$A$21,0)) -> Ownership and control structure | C10: 4 | D10: Ownership chain of two or more layers, however deep, with every layer evidenced from a public register or audited accounts
A11: C2 | B11: =INDEX(Factors!$C$2:$C$21,MATCH($A11,Factors!$A$2:$A$21,0)) -> Ownership and control structure | C11: 5 | D11: Nominee shareholders, bearer shares, or a layer of the ownership chain that cannot be evidenced | E11: 5.3(d)
A12: C3 | B12: =INDEX(Factors!$C$2:$C$21,MATCH($A12,Factors!$A$2:$A$21,0)) -> Industry or occupation | C12: 1 | D12: Salaried employment, pension income, full-time study, or public sector employment
A13: C3 | B13: =INDEX(Factors!$C$2:$C$21,MATCH($A13,Factors!$A$2:$A$21,0)) -> Industry or occupation | C13: 2 | D13: Regulated profession with a named supervisory body outside the financial sector
A14: C3 | B14: =INDEX(Factors!$C$2:$C$21,MATCH($A14,Factors!$A$2:$A$21,0)) -> Industry or occupation | C14: 3 | D14: General retail, hospitality, transport, or construction
A15: C3 | B15: =INDEX(Factors!$C$2:$C$21,MATCH($A15,Factors!$A$2:$A$21,0)) -> Industry or occupation | C15: 4 | D15: Cash-intensive trade or another sector treated as vulnerable, including used vehicle sales, scrap metal, car washes, takeaways, personal care premises, accountancy practices and registered cryptoasset businesses
A16: C3 | B16: =INDEX(Factors!$C$2:$C$21,MATCH($A16,Factors!$A$2:$A$21,0)) -> Industry or occupation | C16: 5 | D16: Money service business, trust or company service provider, or dealer in high-value goods including art and antiquities | E16: 5.3(c)
A17: C4 | B17: =INDEX(Factors!$C$2:$C$21,MATCH($A17,Factors!$A$2:$A$21,0)) -> PEP screening outcome | C17: 1 | D17: No match
A18: C4 | B18: =INDEX(Factors!$C$2:$C$21,MATCH($A18,Factors!$A$2:$A$21,0)) -> PEP screening outcome | C18: 3 | D18: Confirmed match on a family member or known close associate of a politically exposed person, domestic or foreign | E18: 5.3(a)
A19: C4 | B19: =INDEX(Factors!$C$2:$C$21,MATCH($A19,Factors!$A$2:$A$21,0)) -> PEP screening outcome | C19: 4 | D19: Confirmed match: domestic politically exposed person | E19: 5.3(a)
A20: C4 | B20: =INDEX(Factors!$C$2:$C$21,MATCH($A20,Factors!$A$2:$A$21,0)) -> PEP screening outcome | C20: 5 | D20: Confirmed match: foreign politically exposed person, or a PEP in a jurisdiction on either FATF list | E20: 5.3(a)
A21: C5 | B21: =INDEX(Factors!$C$2:$C$21,MATCH($A21,Factors!$A$2:$A$21,0)) -> Adverse media screening outcome | C21: 1 | D21: No match
A22: C5 | B22: =INDEX(Factors!$C$2:$C$21,MATCH($A22,Factors!$A$2:$A$21,0)) -> Adverse media screening outcome | C22: 2 | D22: Match reviewed and discounted as a false positive, with the rationale recorded on file
A23: C5 | B23: =INDEX(Factors!$C$2:$C$21,MATCH($A23,Factors!$A$2:$A$21,0)) -> Adverse media screening outcome | C23: 3 | D23: Adverse media unrelated to financial crime
A24: C5 | B24: =INDEX(Factors!$C$2:$C$21,MATCH($A24,Factors!$A$2:$A$21,0)) -> Adverse media screening outcome | C24: 4 | D24: Adverse media alleging dishonesty or a regulatory breach, no charge brought
A25: C5 | B25: =INDEX(Factors!$C$2:$C$21,MATCH($A25,Factors!$A$2:$A$21,0)) -> Adverse media screening outcome | C25: 5 | D25: Confirmed adverse media relating to financial crime, fraud, bribery, corruption or tax evasion | E25: 5.3(e)
A26: G1 | B26: =INDEX(Factors!$C$2:$C$21,MATCH($A26,Factors!$A$2:$A$21,0)) -> Country of residence or incorporation | C26: 1 | D26: United Kingdom
A27: G1 | B27: =INDEX(Factors!$C$2:$C$21,MATCH($A27,Factors!$A$2:$A$21,0)) -> Country of residence or incorporation | C27: 2 | D27: A country on neither FATF list and not on the HM Treasury high-risk country list
A28: G1 | B28: =INDEX(Factors!$C$2:$C$21,MATCH($A28,Factors!$A$2:$A$21,0)) -> Country of residence or incorporation | C28: 3 | D28: A country on neither list but with materially weaker AML supervision than the UK on a published index
A29: G1 | B29: =INDEX(Factors!$C$2:$C$21,MATCH($A29,Factors!$A$2:$A$21,0)) -> Country of residence or incorporation | C29: 4 | D29: A jurisdiction on the FATF list of Jurisdictions under Increased Monitoring
A30: G1 | B30: =INDEX(Factors!$C$2:$C$21,MATCH($A30,Factors!$A$2:$A$21,0)) -> Country of residence or incorporation | C30: 5 | D30: A jurisdiction on the FATF list of High-Risk Jurisdictions subject to a Call for Action | E30: 5.3(b)
A31: G2 | B31: =INDEX(Factors!$C$2:$C$21,MATCH($A31,Factors!$A$2:$A$21,0)) -> Country of tax residence where different | C31: 1 | D31: No tax residence declared other than the United Kingdom
A32: G2 | B32: =INDEX(Factors!$C$2:$C$21,MATCH($A32,Factors!$A$2:$A$21,0)) -> Country of tax residence where different | C32: 2 | D32: One further tax residence, in a country on neither FATF list
A33: G2 | B33: =INDEX(Factors!$C$2:$C$21,MATCH($A33,Factors!$A$2:$A$21,0)) -> Country of tax residence where different | C33: 4 | D33: A further tax residence in a jurisdiction under Increased Monitoring
A34: G2 | B34: =INDEX(Factors!$C$2:$C$21,MATCH($A34,Factors!$A$2:$A$21,0)) -> Country of tax residence where different | C34: 5 | D34: A further tax residence in a Call for Action jurisdiction | E34: 5.3(b)
A35: G3 | B35: =INDEX(Factors!$C$2:$C$21,MATCH($A35,Factors!$A$2:$A$21,0)) -> Expected counterparty or payment corridor countries | C35: 1 | D35: United Kingdom only
A36: G3 | B36: =INDEX(Factors!$C$2:$C$21,MATCH($A36,Factors!$A$2:$A$21,0)) -> Expected counterparty or payment corridor countries | C36: 2 | D36: The United Kingdom and countries on neither FATF list
A37: G3 | B37: =INDEX(Factors!$C$2:$C$21,MATCH($A37,Factors!$A$2:$A$21,0)) -> Expected counterparty or payment corridor countries | C37: 3 | D37: Any corridor to a country with materially weaker AML supervision, on neither list
A38: G3 | B38: =INDEX(Factors!$C$2:$C$21,MATCH($A38,Factors!$A$2:$A$21,0)) -> Expected counterparty or payment corridor countries | C38: 4 | D38: Any corridor to a jurisdiction under Increased Monitoring
A39: G3 | B39: =INDEX(Factors!$C$2:$C$21,MATCH($A39,Factors!$A$2:$A$21,0)) -> Expected counterparty or payment corridor countries | C39: 5 | D39: Any corridor to a Call for Action jurisdiction | E39: 5.3(b)
A40: P1 | B40: =INDEX(Factors!$C$2:$C$21,MATCH($A40,Factors!$A$2:$A$21,0)) -> Product type held | C40: 1 | D40: Instant-access savings account only
...

Sheet Escalators
A1: Reference | B1: Effect | C1: Condition
A2: 5.3(a) | B2: Mandatory High | C2: The customer, a beneficial owner or a person exercising control is a politically exposed person, a family member or a known close associate.
A3: 5.3(b) | B3: Mandatory High | C3: The customer resides in, has a further tax residence in, or sends money to or receives money from a jurisdiction identified by FATF as a High-Risk Jurisdiction subject to a Call for Action. Regulation 33(1)(b) requires enhanced due diligence where the customer is established in such a jurisdiction; the Bank applies the escalator to payment corridors as well, which regulation 33(1) permits because it sets a floor and not a ceiling.
A4: 5.3(c) | B4: Mandatory High | C4: The customer is a money service business, a trust or company service provider, or a dealer in high-value goods.
A5: 5.3(d) | B5: Mandatory High | C5: The ownership structure includes nominee shareholders, bearer shares, or an entity incorporated in a jurisdiction with no accessible beneficial ownership register. Because level 5 of factor C1 covers trusts, nominee arrangements and overseas incorporation together, the recorded level cannot tell those apart; the escalator therefore fires on the whole of C1 level 5. That is deliberately conservative and it is the wrong way round: the fix is to split C1 level 5 so the condition can be evaluated, and that is a library change requiring approval (methodology 11.9a).
A6: 5.3(e) | B6: Mandatory High | C6: Screening returns a confirmed adverse media match relating to financial crime, fraud, bribery, corruption or tax evasion.
A7: 5.3(f) | B7: Mandatory High | C7: A suspicious activity report has been submitted in respect of the customer in the preceding twelve months.
A8: 5.4(a) | B8: Prohibited | C8: A confirmed sanctions match. Referred to the Sanctions team and handled under the sanctions procedure, not under this model.
A9: 5.4(b) | B9: Prohibited | C9: Shell banks.
A10: 5.4(c) | B10: Prohibited | C10: A money service business or cryptoasset business operating in the UK without the registration it is required to hold.
A11: 5.4(d) | B11: Prohibited | C11: The customer does not provide information the Bank needs to complete customer due diligence (reg. 31).
A12: 5.4(e) | B12: Prohibited | C12: The Bank cannot identify the beneficial owner, or is not satisfied that it knows who they are.
C14: Mandatory High overrides the arithmetic. A weighted average dilutes a single severe factor by design; this list is the compensating control. Prohibited relationships are not scored at all.

Sheet Example
A1: Worked example: customer 4417
A2: Sole trader, UK resident, onboarded through the mobile app with electronic identity verification. Trades in used motor vehicles. Declares turnover of GBP 15,000 to GBP 25,000 a month, of which roughly half is expected in cash. No adverse media, no PEP match, simple ownership. Scores in blue are the analyst's selections; everything else is calculated.
H3: Category scores
A4: Factor | B4: Factor name | C4: Score | D4: Effective weight | E4: Contribution | F4: Level selected | H4: Code | I4: Category | J4: Score | K4: Weight
A5: C1 | B5: =INDEX(Factors!$C$2:$C$21,MATCH($A5,Factors!$A$2:$A$21,0)) -> Customer legal form | C5: 2 | D5: =INDEX(Factors!$E$2:$E$21,MATCH($A5,Factors!$A$2:$A$21,0)) -> 0.06 | E5: =$D5*$C5 -> 0.12 | F5: =INDEX(Levels!$D$2:$D$99,MATCH(1,INDEX((Levels!$A$2:$A$99=$A5)*(Levels!$C$2:$C$99=$C5),0),0)) -> Joint personal account between parties with an evidenced relationship, or a UK-registered sole trader | H5: C | I5: Customer | J5: =SUMPRODUCT((Factors!$B$2:$B$21=$H5)*Factors!$D$2:$D$21*$C$5:$C$24) -> 1.95 | K5: =INDEX(Categories!$C$2:$C$6,MATCH($H5,Categories!$A$2:$A$6,0)) -> 0.3
A6: C2 | B6: =INDEX(Factors!$C$2:$C$21,MATCH($A6,Factors!$A$2:$A$21,0)) -> Ownership and control structure | C6: 1 | D6: =INDEX(Factors!$E$2:$E$21,MATCH($A6,Factors!$A$2:$A$21,0)) -> 0.06 | E6: =$D6*$C6 -> 0.06 | F6: =INDEX(Levels!$D$2:$D$99,MATCH(1,INDEX((Levels!$A$2:$A$99=$A6)*(Levels!$C$2:$C$99=$C6),0),0)) -> Natural person; no beneficial ownership analysis required | H6: G | I6: Geography | J6: =SUMPRODUCT((Factors!$B$2:$B$21=$H6)*Factors!$D$2:$D$21*$C$5:$C$24) -> 1 | K6: =INDEX(Categories!$C$2:$C$6,MATCH($H6,Categories!$A$2:$A$6,0)) -> 0.25
A7: C3 | B7: =INDEX(Factors!$C$2:$C$21,MATCH($A7,Factors!$A$2:$A$21,0)) -> Industry or occupation | C7: 4 | D7: =INDEX(Factors!$E$2:$E$21,MATCH($A7,Factors!$A$2:$A$21,0)) -> 0.075 | E7: =$D7*$C7 -> 0.3 | F7: =INDEX(Levels!$D$2:$D$99,MATCH(1,INDEX((Levels!$A$2:$A$99=$A7)*(Levels!$C$2:$C$99=$C7),0),0)) -> Cash-intensive trade or another sector treated as vulnerable, including used vehicle sales, scrap metal, car washes, takeaways, personal care premises, accountancy practices and registered cryptoasset businesses | H7: P | I7: Product and service | J7: =SUMPRODUCT((Factors!$B$2:$B$21=$H7)*Factors!$D$2:$D$21*$C$5:$C$24) -> 3.05 | K7: =INDEX(Categories!$C$2:$C$6,MATCH($H7,Categories!$A$2:$A$6,0)) -> 0.2
A8: C4 | B8: =INDEX(Factors!$C$2:$C$21,MATCH($A8,Factors!$A$2:$A$21,0)) -> PEP screening outcome | C8: 1 | D8: =INDEX(Factors!$E$2:$E$21,MATCH($A8,Factors!$A$2:$A$21,0)) -> 0.06 | E8: =$D8*$C8 -> 0.06 | F8: =INDEX(Levels!$D$2:$D$99,MATCH(1,INDEX((Levels!$A$2:$A$99=$A8)*(Levels!$C$2:$C$99=$C8),0),0)) -> No match | H8: D | I8: Delivery channel | J8: =SUMPRODUCT((Factors!$B$2:$B$21=$H8)*Factors!$D$2:$D$21*$C$5:$C$24) -> 2.6 | K8: =INDEX(Categories!$C$2:$C$6,MATCH($H8,Categories!$A$2:$A$6,0)) -> 0.1
A9: C5 | B9: =INDEX(Factors!$C$2:$C$21,MATCH($A9,Factors!$A$2:$A$21,0)) -> Adverse media screening outcome | C9: 1 | D9: =INDEX(Factors!$E$2:$E$21,MATCH($A9,Factors!$A$2:$A$21,0)) -> 0.045 | E9: =$D9*$C9 -> 0.045 | F9: =INDEX(Levels!$D$2:$D$99,MATCH(1,INDEX((Levels!$A$2:$A$99=$A9)*(Levels!$C$2:$C$99=$C9),0),0)) -> No match | H9: A | I9: Expected activity | J9: =SUMPRODUCT((Factors!$B$2:$B$21=$H9)*Factors!$D$2:$D$21*$C$5:$C$24) -> 2.45 | K9: =INDEX(Categories!$C$2:$C$6,MATCH($H9,Categories!$A$2:$A$6,0)) -> 0.15
A10: G1 | B10: =INDEX(Factors!$C$2:$C$21,MATCH($A10,Factors!$A$2:$A$21,0)) -> Country of residence or incorporation | C10: 1 | D10: =INDEX(Factors!$E$2:$E$21,MATCH($A10,Factors!$A$2:$A$21,0)) -> 0.1 | E10: =$D10*$C10 -> 0.1 | F10: =INDEX(Levels!$D$2:$D$99,MATCH(1,INDEX((Levels!$A$2:$A$99=$A10)*(Levels!$C$2:$C$99=$C10),0),0)) -> United Kingdom
A11: G2 | B11: =INDEX(Factors!$C$2:$C$21,MATCH($A11,Factors!$A$2:$A$21,0)) -> Country of tax residence where different | C11: 1 | D11: =INDEX(Factors!$E$2:$E$21,MATCH($A11,Factors!$A$2:$A$21,0)) -> 0.05 | E11: =$D11*$C11 -> 0.05 | F11: =INDEX(Levels!$D$2:$D$99,MATCH(1,INDEX((Levels!$A$2:$A$99=$A11)*(Levels!$C$2:$C$99=$C11),0),0)) -> No tax residence declared other than the United Kingdom
A12: G3 | B12: =INDEX(Factors!$C$2:$C$21,MATCH($A12,Factors!$A$2:$A$21,0)) -> Expected counterparty or payment corridor countries | C12: 1 | D12: =INDEX(Factors!$E$2:$E$21,MATCH($A12,Factors!$A$2:$A$21,0)) -> 0.1 | E12: =$D12*$C12 -> 0.1 | F12: =INDEX(Levels!$D$2:$D$99,MATCH(1,INDEX((Levels!$A$2:$A$99=$A12)*(Levels!$C$2:$C$99=$C12),0),0)) -> United Kingdom only
A13: P1 | B13: =INDEX(Factors!$C$2:$C$21,MATCH($A13,Factors!$A$2:$A$21,0)) -> Product type held | C13: 4 | D13: =INDEX(Factors!$E$2:$E$21,MATCH($A13,Factors!$A$2:$A$21,0)) -> 0.07 | E13: =$D13*$C13 -> 0.28 | F13: =INDEX(Levels!$D$2:$D$99,MATCH(1,INDEX((Levels!$A$2:$A$99=$A13)*(Levels!$C$2:$C$99=$C13),0),0)) -> Business current account without cash handling or international payments
A14: P2 | B14: =INDEX(Factors!$C$2:$C$21,MATCH($A14,Factors!$A$2:$A$21,0)) -> Cash functionality | C14: 5 | D14: =INDEX(Factors!$E$2:$E$21,MATCH($A14,Factors!$A$2:$A$21,0)) -> 0.05 | E14: =$D14*$C14 -> 0.25 | F14: =INDEX(Levels!$D$2:$D$99,MATCH(1,INDEX((Levels!$A$2:$A$99=$A14)*(Levels!$C$2:$C$99=$C14),0),0)) -> Cash deposits expected above GBP 10,000 a month, or use of a cash collection service
A15: P3 | B15: =INDEX(Factors!$C$2:$C$21,MATCH($A15,Factors!$A$2:$A$21,0)) -> International payment functionality | C15: 1 | D15: =INDEX(Factors!$E$2:$E$21,MATCH($A15,Factors!$A$2:$A$21,0)) -> 0.05 | E15: =$D15*$C15 -> 0.05 | F15: =INDEX(Levels!$D$2:$D$99,MATCH(1,INDEX((Levels!$A$2:$A$99=$A15)*(Levels!$C$2:$C$99=$C15),0),0)) -> Not enabled on the account
A16: P4 | B16: =INDEX(Factors!$C$2:$C$21,MATCH($A16,Factors!$A$2:$A$21,0)) -> Third-party access to the account | C16: 1 | D16: =INDEX(Factors!$E$2:$E$21,MATCH($A16,Factors!$A$2:$A$21,0)) -> 0.03 | E16: =$D16*$C16 -> 0.03 | F16: =INDEX(Levels!$D$2:$D$99,MATCH(1,INDEX((Levels!$A$2:$A$99=$A16)*(Levels!$C$2:$C$99=$C16),0),0)) -> Sole named party, no third-party access
A17: D1 | B17: =INDEX(Factors!$C$2:$C$21,MATCH($A17,Factors!$A$2:$A$21,0)) -> Onboarding channel | C17: 3 | D17: =INDEX(Factors!$E$2:$E$21,MATCH($A17,Factors!$A$2:$A$21,0)) -> 0.045 | E17: =$D17*$C17 -> 0.135 | F17: =INDEX(Levels!$D$2:$D$99,MATCH(1,INDEX((Levels!$A$2:$A$99=$A17)*(Levels!$C$2:$C$99=$C17),0),0)) -> Digital application completed by the customer on the Bank's own app or website
A18: D2 | B18: =INDEX(Factors!$C$2:$C$21,MATCH($A18,Factors!$A$2:$A$21,0)) -> Identity verification method | C18: 3 | D18: =INDEX(Factors!$E$2:$E$21,MATCH($A18,Factors!$A$2:$A$21,0)) -> 0.035 | E18: =$D18*$C18 -> 0.105 | F18: =INDEX(Levels!$D$2:$D$99,MATCH(1,INDEX((Levels!$A$2:$A$99=$A18)*(Levels!$C$2:$C$99=$C18),0),0)) -> Electronic verification returning two or more independent matching sources
A19: D3 | B19: =INDEX(Factors!$C$2:$C$21,MATCH($A19,Factors!$A$2:$A$21,0)) -> Introduction source | C19: 1 | D19: =INDEX(Factors!$E$2:$E$21,MATCH($A19,Factors!$A$2:$A$21,0)) -> 0.02 | E19: =$D19*$C19 -> 0.02 | F19: =INDEX(Levels!$D$2:$D$99,MATCH(1,INDEX((Levels!$A$2:$A$99=$A19)*(Levels!$C$2:$C$99=$C19),0),0)) -> Direct application by the customer
A20: A1 | B20: =INDEX(Factors!$C$2:$C$21,MATCH($A20,Factors!$A$2:$A$21,0)) -> Expected turnover relative to declared income | C20: 2 | D20: =INDEX(Factors!$E$2:$E$21,MATCH($A20,Factors!$A$2:$A$21,0)) -> 0.0375 | E20: =$D20*$C20 -> 0.075 | F20: =INDEX(Levels!$D$2:$D$99,MATCH(1,INDEX((Levels!$A$2:$A$99=$A20)*(Levels!$C$2:$C$99=$C20),0),0)) -> Consistent with declared income or turnover, GBP 5,000 to GBP 25,000 a month
A21: A2 | B21: =INDEX(Factors!$C$2:$C$21,MATCH($A21,Factors!$A$2:$A$21,0)) -> Expected cash proportion of credits | C21: 4 | D21: =INDEX(Factors!$E$2:$E$21,MATCH($A21,Factors!$A$2:$A$21,0)) -> 0.045 | E21: =$D21*$C21 -> 0.18 | F21: =INDEX(Levels!$D$2:$D$99,MATCH(1,INDEX((Levels!$A$2:$A$99=$A21)*(Levels!$C$2:$C$99=$C21),0),0)) -> Above 30% and up to 60% of expected monthly credits
... A24: A5 | B24: =INDEX(Factors!$C$2:$C$21,MATCH($A24,Factors!$A$2:$A$21,0)) -> Plausibility of the declared profile | C24: 1 | D24: =INDEX(Factors!$E$2:$E$21,MATCH($A24,Factors!$A$2:$A$21,0)) -> 0.015 | E24: =$D24*$C24 -> 0.015 | F24: =INDEX(Levels!$D$2:$D$99,MATCH(1,INDEX((Levels!$A$2:$A$99=$A24)*(Levels!$C$2:$C$99=$C24),0),0)) -> Declared activity is consistent with every other item on file
G26: Weighted score | I26: =SUM($E$5:$E$24) -> 2.0725
G27: Rounded to two decimal places | I27: =ROUND($I26,2) -> 2.07
G28: Band from the arithmetic | I28: =IF($I27<=2,"Low",IF($I27<=3.49,"Medium","High")) -> Medium
G29: Mandatory escalator applies (Yes or No) | I29: No
G30: Final customer risk rating | I30: =IF($I29="Yes","High",$I28) -> Medium
G32: The model rates this customer just inside Medium. It is cash-intensive, non-face-to-face and in a sector the National Risk Assessment treats as vulnerable, yet the geography category scores the minimum and pulls the average down. Whether that is the right answer is what Step 4 is for.

Sheet Checks
A1: Integrity checks
A2: Every row must read OK. These recalculate whenever a weight or a level is changed.
A4: # | B4: What is tested | C4: Result | D4: Expected | E4: Status
A5: 1 | B5: Category weights sum to 100% | C5: =ROUND(SUM(Categories!$C$2:$C$6),6) -> 1 | D5: 1 | E5: =IF($C5=$D5,"OK","CHECK") -> OK
A6: 2 | B6: Factor weights sum to 100% inside every category | C6: =SUMPRODUCT(--(ROUND(Categories!$E$2:$E$6,6)<>1)) -> 0 | D6: 0 | E6: =IF($C6=$D6,"OK","CHECK") -> OK
A7: 3 | B7: Effective weights sum to 100% | C7: =ROUND(SUM(Factors!$E$2:$E$21),6) -> 1 | D7: 1 | E7: =IF($C7=$D7,"OK","CHECK") -> OK
A8: 4 | B8: No duplicate factor codes | C8: =SUMPRODUCT(--(COUNTIF(Factors!$A$2:$A$21,Factors!$A$2:$A$21)>1)) -> 0 | D8: 0 | E8: =IF($C8=$D8,"OK","CHECK") -> OK
A9: 5 | B9: Every level row points at a factor that exists | C9: =SUMPRODUCT(--(COUNTIF(Factors!$A$2:$A$21,Levels!$A$2:$A$99)=0)) -> 0 | D9: 0 | E9: =IF($C9=$D9,"OK","CHECK") -> OK
A10: 6 | B10: Every factor has at least four levels | C10: =SUMPRODUCT(--(COUNTIF(Levels!$A$2:$A$99,Factors!$A$2:$A$21)<4)) -> 0 | D10: 0 | E10: =IF($C10=$D10,"OK","CHECK") -> OK
A11: 7 | B11: No score outside the range 1 to 5 | C11: =SUMPRODUCT(--((Levels!$C$2:$C$99<1)+(Levels!$C$2:$C$99>5)>0)) -> 0 | D11: 0 | E11: =IF($C11=$D11,"OK","CHECK") -> OK
A12: 8 | B12: No duplicate score within a factor | C12: =SUMPRODUCT(--(COUNTIFS(Levels!$A$2:$A$99,Levels!$A$2:$A$99,Levels!$C$2:$C$99,Levels!$C$2:$C$99)>1)) -> 0 | D12: 0 | E12: =IF($C12=$D12,"OK","CHECK") -> OK
A13: 9 | B13: Every factor's lowest level is 1 | C13: =SUMPRODUCT(--(Factors!$F$2:$F$21<>1)) -> 0 | D13: 0 | E13: =IF($C13=$D13,"OK","CHECK") -> OK
A14: 10 | B14: Every factor's highest level is 5 | C14: =SUMPRODUCT(--(Factors!$G$2:$G$21<>5)) -> 0 | D14: 0 | E14: =IF($C14=$D14,"OK","CHECK") -> OK
A15: 11 | B15: Lowest overall score the model can produce | C15: =ROUND(SUMPRODUCT(Factors!$E$2:$E$21,Factors!$F$2:$F$21),2) -> 1 | D15: 1 | E15: =IF($C15=$D15,"OK","CHECK") -> OK
A16: 12 | B16: Highest overall score the model can produce | C16: =ROUND(SUMPRODUCT(Factors!$E$2:$E$21,Factors!$G$2:$G$21),2) -> 5 | D16: 5 | E16: =IF($C16=$D16,"OK","CHECK") -> OK
A17: 13 | B17: Worked example scores exactly as documented (2.07) | C17: =ROUND(SUM(Example!$E$5:$E$24),2) -> 2.07 | D17: 2.07 | E17: =IF($C17=$D17,"OK","CHECK") -> OK
B19: Overall status | E19: =IF(COUNTIF($E$5:$E$17,"CHECK")=0,"ALL OK","FIX") -> ALL OK
B21: Checks 11 and 12 cannot fail while checks 1 to 3, 9 and 10 pass: if every factor runs from 1 to 5 and the weights sum to 100%, the achievable range is 1.00 to 5.00 by arithmetic. They are kept because they evaluate the aggregation formula itself, so a mistyped range or a transposed weight vector fails here and nowhere else in this workbook. They say nothing about the level definitions. See docs/02-risk-factor-rationale.md, 8.2a.
